{
    "registryname": "transformlp",
    "localizedname": "鲜血转化",
    "color": "DC143C",
    "modifiers": [
        {
            "elements": "modularmachinery:blockcasing@3",
            "x": -1,
            "y": 0,
            "z": 0,
            "description": "控制器紧挨着的方块换成此方块以提高10%产品产出率！",
            "modifier": {
                "io": "output",
                "target": "item",
                "operation": 1,
                "multiplier": 1.1,
                "affectChance": true
            }
        },
        {
            "elements": "modularmachinery:blockcasing@2",
            "x": -2,
            "y": 0,
            "z": 0,
            "description": "控制器紧挨着的方块换成此方块以降低能源消耗20%！",
            "modifier": {
                "io": "input",
                "target": "energy",
                "operation": 1,
                "multiplier": 0.8,
                "affectChance": true
            }
        }
    ],
	"parts": [
        {
            "x": -1,
            "y": 0,
            "z": 0,
            
            "elements": [
                "casings_all"
            ]
        },
        {
            "x": -2,
            "y": 0,
            "z": 2,
            "elements": [
                "bloodmagic:blood_rune@0"
            ]
        },
        {
            "x": 1,
            "y": 0,
            "z": 0,
            
            "elements": [
                "casings_all"
            ]
        },
        {
            "x": 2,
            "y": 2,
            "z": 1,
            "elements": [
                "extrautils2:ineffableglass@3"
            ]
        },
        {
            "x": -3,
            "y": 0,
            "z": 4,
            "elements": [
                "bloodmagic:path@2"
            ]
        },
        {
            "x": -1,
            "y": 0,
            "z": 2,
            "elements": [
                "naturesaura:infused_stone@0"
            ]
        },
        {
            "x": -2,
            "y": 0,
            "z": 0,
            "elements": [
                "bloodmagic:path@2"
            ]
        },
        {
            "x": -3,
            "y": 0,
            "z": 0,
            "elements": [
                "bloodmagic:path@2"
            ]
        },
        {
            "x": 2,
            "y": 0,
            "z": 0,
            "elements": [
                "bloodmagic:path@2"
            ]
        },
        {
            "x": 0,
            "y": 0,
            "z": 2,
            "elements": [
                "bloodmagic:blood_rune@0"
            ]
        },
        {
            "x": -2,
            "y": 0,
            "z": 4,
            "elements": [
                "bloodmagic:path@2"
            ]
        },
        {
            "x": 3,
            "y": 0,
            "z": 0,
            "elements": [
                "bloodmagic:path@2"
            ]
        },
        {
            "x": 2,
            "y": 2,
            "z": 3,
            "elements": [
                "extrautils2:ineffableglass@3"
            ]
        },
        {
            "x": -1,
            "y": 0,
            "z": 4,
            
            "elements": [
                "casings_all"
            ]
        },
        {
            "x": 1,
            "y": 0,
            "z": 2,
            "elements": [
                "naturesaura:infused_stone@0"
            ]
        },
        {
            "x": 2,
            "y": 0,
            "z": 2,
            "elements": [
                "bloodmagic:blood_rune@0"
            ]
        },
        {
            "x": 0,
            "y": 0,
            "z": 4,
            "elements": [
                "bloodmagic:blood_rune@0"
            ]
        },
        {
            "x": 1,
            "y": 0,
            "z": 4,
            
            "elements": [
                "casings_all"
            ]
        },
        {
            "x": 2,
            "y": 0,
            "z": 4,
            "elements": [
                "bloodmagic:path@2"
            ]
        },
        {
            "x": 3,
            "y": 0,
            "z": 4,
            "elements": [
                "bloodmagic:path@2"
            ]
        },
        {
            "x": -2,
            "y": 3,
            "z": 1,
            "elements": [
                "extrautils2:ineffableglass@3"
            ]
        },
        {
            "x": -2,
            "y": 1,
            "z": 0,
            
            "elements": [
                "casings_all"
            ]
        },
        {
            "x": -1,
            "y": 1,
            "z": 0,
            "elements": [
                "extrautils2:ineffableglass@3"
            ]
        },
        {
            "x": -2,
            "y": 3,
            "z": 3,
            "elements": [
                "extrautils2:ineffableglass@3"
            ]
        },
        {
            "x": 0,
            "y": 1,
            "z": 0,
            "elements": [
                "extrautils2:ineffableglass@3"
            ]
        },
        {
            "x": -2,
            "y": 1,
            "z": 2,
            "elements": [
                "extrautils2:ineffableglass@3"
            ]
        },
        {
            "x": 1,
            "y": 1,
            "z": 0,
            "elements": [
                "extrautils2:ineffableglass@3"
            ]
        },
        {
            "x": 2,
            "y": 3,
            "z": 1,
            "elements": [
                "extrautils2:ineffableglass@3"
            ]
        },
        {
            "x": -1,
            "y": 1,
            "z": 2,
            "elements": [
                "minecraft:lava"
            ]
        },
        {
            "x": 0,
            "y": 1,
            "z": 2,
            "elements": [
                "bloodmagic:demon_crucible@0"
            ]
        },
        {
            "x": 2,
            "y": 1,
            "z": 0,
            
            "elements": [
                "casings_all"
            ]
        },
        {
            "x": -2,
            "y": 1,
            "z": 4,
            
            "elements": [
                "casings_all"
            ]
        },
        {
            "x": 2,
            "y": 3,
            "z": 3,
            "elements": [
                "extrautils2:ineffableglass@3"
            ]
        },
        {
            "x": -1,
            "y": 1,
            "z": 4,
            "elements": [
                "extrautils2:ineffableglass@3"
            ]
        },
        {
            "x": 1,
            "y": 1,
            "z": 2,
            "elements": [
                "minecraft:lava"
            ]
        },
        {
            "x": 2,
            "y": 1,
            "z": 2,
            "elements": [
                "extrautils2:ineffableglass@3"
            ]
        },
        {
            "x": 0,
            "y": 1,
            "z": 4,
            "elements": [
                "extrautils2:ineffableglass@3"
            ]
        },
        {
            "x": 1,
            "y": 1,
            "z": 4,
            "elements": [
                "extrautils2:ineffableglass@3"
            ]
        },
        {
            "x": 2,
            "y": 1,
            "z": 4,
            
            "elements": [
                "casings_all"
            ]
        },
        {
            "x": -2,
            "y": 2,
            "z": 0,
            "elements": [
                "bloodmagic:blood_rune@0"
            ]
        },
        {
            "x": -1,
            "y": 4,
            "z": 1,
            "elements": [
                "bloodmagic:decorative_brick@0"
            ]
        },
        {
            "x": -1,
            "y": 2,
            "z": 0,
            "elements": [
                "extrautils2:ineffableglass@3"
            ]
        },
        {
            "x": 0,
            "y": 4,
            "z": 1,
            "elements": [
                "extrautils2:ineffableglass@3"
            ]
        },
        {
            "x": 0,
            "y": 2,
            "z": 0,
            "elements": [
                "extrautils2:ineffableglass@3"
            ]
        },
        {
            "x": 2,
            "y": 0,
            "z": -1,
            "elements": [
                "bloodmagic:path@2"
            ]
        },
        {
            "x": -2,
            "y": 2,
            "z": 2,
            "elements": [
                "extrautils2:ineffableglass@3"
            ]
        },
        {
            "x": -1,
            "y": 4,
            "z": 3,
            "elements": [
                "bloodmagic:decorative_brick@0"
            ]
        },
        {
            "x": 1,
            "y": 4,
            "z": 1,
            "elements": [
                "bloodmagic:decorative_brick@0"
            ]
        },
        {
            "x": 1,
            "y": 2,
            "z": 0,
            "elements": [
                "extrautils2:ineffableglass@3"
            ]
        },
        {
            "x": -2,
            "y": 0,
            "z": 1,
            
            "elements": [
                "casings_all"
            ]
        },
        {
            "x": 0,
            "y": 4,
            "z": 3,
            "elements": [
                "extrautils2:ineffableglass@3"
            ]
        },
        {
            "x": 0,
            "y": 2,
            "z": 2,
            "elements": [
                "bloodmagic:inversion_pillar@0"
            ]
        },
        {
            "x": 2,
            "y": 2,
            "z": 0,
            "elements": [
                "bloodmagic:blood_rune@0"
            ]
        },
        {
            "x": -2,
            "y": 2,
            "z": 4,
            "elements": [
                "bloodmagic:blood_rune@0"
            ]
        },
        {
            "x": 1,
            "y": 4,
            "z": 3,
            "elements": [
                "bloodmagic:decorative_brick@0"
            ]
        },
        {
            "x": -1,
            "y": 0,
            "z": 1,
            "elements": [
                "naturesaura:infused_stone@0"
            ]
        },
        {
            "x": -1,
            "y": 2,
            "z": 4,
            "elements": [
                "extrautils2:ineffableglass@3"
            ]
        },
        {
            "x": -2,
            "y": 0,
            "z": 3,
            
            "elements": [
                "casings_all"
            ]
        },
        {
            "x": 0,
            "y": 0,
            "z": 1,
            "elements": [
                "naturesaura:infused_stone@0"
            ]
        },
        {
            "x": -2,
            "y": 0,
            "z": -1,
            "elements": [
                "bloodmagic:path@2"
            ]
        },
        {
            "x": 2,
            "y": 2,
            "z": 2,
            "elements": [
                "extrautils2:ineffableglass@3"
            ]
        },
        {
            "x": 0,
            "y": 2,
            "z": 4,
            "elements": [
                "extrautils2:ineffableglass@3"
            ]
        },
        {
            "x": 1,
            "y": 0,
            "z": 1,
            "elements": [
                "naturesaura:infused_stone@0"
            ]
        },
        {
            "x": -1,
            "y": 0,
            "z": 3,
            "elements": [
                "naturesaura:infused_stone@0"
            ]
        },
        {
            "x": 2,
            "y": 0,
            "z": 1,
            
            "elements": [
                "casings_all"
            ]
        },
        {
            "x": 1,
            "y": 2,
            "z": 4,
            "elements": [
                "extrautils2:ineffableglass@3"
            ]
        },
        {
            "x": -2,
            "y": 0,
            "z": 5,
            "elements": [
                "bloodmagic:path@2"
            ]
        },
        {
            "x": 0,
            "y": 0,
            "z": 3,
            "elements": [
                "naturesaura:infused_stone@0"
            ]
        },
        {
            "x": 2,
            "y": 2,
            "z": 4,
            "elements": [
                "bloodmagic:blood_rune@0"
            ]
        },
        {
            "x": 1,
            "y": 0,
            "z": 3,
            "elements": [
                "naturesaura:infused_stone@0"
            ]
        },
        {
            "x": 2,
            "y": 0,
            "z": 3,
            
            "elements": [
                "casings_all"
            ]
        },
        {
            "x": 2,
            "y": 0,
            "z": 5,
            "elements": [
                "bloodmagic:path@2"
            ]
        },
        {
            "x": -1,
            "y": 3,
            "z": 0,
            "elements": [
                "extrautils2:ineffableglass@3"
            ]
        },
        {
            "x": 0,
            "y": 3,
            "z": 0,
            "elements": [
                "extrautils2:ineffableglass@3"
            ]
        },
        {
            "x": -2,
            "y": 3,
            "z": 2,
            "elements": [
                "extrautils2:ineffableglass@3"
            ]
        },
        {
            "x": 1,
            "y": 3,
            "z": 0,
            "elements": [
                "extrautils2:ineffableglass@3"
            ]
        },
        {
            "x": -2,
            "y": 1,
            "z": 1,
            "elements": [
                "extrautils2:ineffableglass@3"
            ]
        },
        {
            "x": -1,
            "y": 1,
            "z": 1,
            "elements": [
                "minecraft:lava"
            ]
        },
        {
            "x": -1,
            "y": 3,
            "z": 4,
            "elements": [
                "extrautils2:ineffableglass@3"
            ]
        },
        {
            "x": -2,
            "y": 1,
            "z": 3,
            "elements": [
                "extrautils2:ineffableglass@3"
            ]
        },
        {
            "x": 0,
            "y": 1,
            "z": 1,
            "elements": [
                "minecraft:lava"
            ]
        },
        {
            "x": 2,
            "y": 3,
            "z": 2,
            "elements": [
                "extrautils2:ineffableglass@3"
            ]
        },
        {
            "x": 0,
            "y": 3,
            "z": 4,
            "elements": [
                "extrautils2:ineffableglass@3"
            ]
        },
        {
            "x": -1,
            "y": 1,
            "z": 3,
            "elements": [
                "minecraft:lava"
            ]
        },
        {
            "x": 1,
            "y": 1,
            "z": 1,
            "elements": [
                "minecraft:lava"
            ]
        },
        {
            "x": 2,
            "y": 1,
            "z": 1,
            "elements": [
                "extrautils2:ineffableglass@3"
            ]
        },
        {
            "x": 1,
            "y": 3,
            "z": 4,
            "elements": [
                "extrautils2:ineffableglass@3"
            ]
        },
        {
            "x": 0,
            "y": 1,
            "z": 3,
            "elements": [
                "minecraft:lava"
            ]
        },
        {
            "x": 1,
            "y": 1,
            "z": 3,
            "elements": [
                "minecraft:lava"
            ]
        },
        {
            "x": 2,
            "y": 1,
            "z": 3,
            "elements": [
                "extrautils2:ineffableglass@3"
            ]
        },
        {
            "x": -2,
            "y": 2,
            "z": 1,
            "elements": [
                "extrautils2:ineffableglass@3"
            ]
        },
        {
            "x": -1,
            "y": 4,
            "z": 2,
            "elements": [
                "extrautils2:ineffableglass@3"
            ]
        },
        {
            "x": 0,
            "y": 4,
            "z": 2,
            
            "elements": [
                "casings_all"
            ]
        },
        {
            "x": -2,
            "y": 2,
            "z": 3,
            "elements": [
                "extrautils2:ineffableglass@3"
            ]
        },
        {
            "x": 1,
            "y": 4,
            "z": 2,
            "elements": [
                "extrautils2:ineffableglass@3"
            ]
        }
    ]}